Workbook
Name _Div1: #REF!
Name _Div1: #REF!
Name _Div2: #REF!
Name _Div2: #REF!
Name _Div3: #REF!
Name _Div3: #REF!
Name _Div4: #REF!
Name _Div4: #REF!
Name _Regression_Int: 1
Name coup: [1]Convexity!$C$7
Name g_firm: #REF!
Name g_firm: #REF!
Name g_firm: #REF!
Name IQ_CH: 110000
Name IQ_CQ: 5000
Name IQ_CY: 10000
Name IQ_DAILY: 500000
Name IQ_FH: 100000
Name IQ_FQ: 500
Name IQ_FY: 1000
Name IQ_LTM: 2000
Name IQ_MONTH: 15000
Name IQ_NTM: 6000
Name IQ_WEEK: 50000
Name IQ_YTD: 3000
Name k: #REF!
Name k: #REF!
Name k: #REF!
Name k_eq: #REF!
Name k_eq: #REF!
Name mat: [1]Convexity!$C$9
Name price: [1]Convexity!$C$10
Name Price4: #REF!
Name Price4: #REF!
Name Price4: #REF!
Name Print_Area_MI: #REF!
Name Print_Area_MI: #REF!
Name rdebt: #REF!
Name rdebt: #REF!
Name Selling_Price: '[2]Base Case'!$B$11
Name tax_rate: #REF!
Name tax_rate: #REF!
Name tax_rate: #REF!
Name taxtable: #REF!
Name taxtable: #REF!
Name taxtable: #REF!
Name taxtable: #REF!
Name taxtable: #REF!
Name term_g: #REF!
Name term_g: #REF!
Name Variable_Cost_per_unit: '[2]Base Case'!$B$12
Name WACC_5: #REF!
Name WACC_5: #REF!
Name WACC_5: #REF!
Name ytm: [1]Convexity!$C$8

Sheet Capital Allocation
B2: Capital Allocation. Optimal Captial Allocation using Maixum Utility
B3: Capital Allocation > Asset Classes Allocation > Security Selection
B5: Risky Pf (P) only
B6: rf: rate of return of risk-free asset | D6: ='Data. Securities'!E7 -> 0.04246
B7: E(Rp): expected return of risky pf | D7: ='Asset Classes Allocation'!D26 -> 0.1833731
B8: 𝜎 p: SD of risky pf | D8: ='Asset Classes Allocation'!E26 -> 0.19104045
B10: Complete Pf (C). Risk free + Risky Pf
B11: y: weight of risky pf | D11: =(D7-D6)/(D17*D8^2) -> 0.52175782
B12: 1-y: weight of risk free asset | D12: =1-D11 -> 0.47824218
B13: E(rc): expected return of the Complete pf | D13: =D11*D7+D12*D6 -> 0.11598251
B14: 𝜎 c: SD of Complete pf | D14: =D11*D8 -> 0.099676851
B15: Slope: Capital Allocation Line ( Sharpe) | D15: =(D7-D6)/D8 -> 0.73760869
B16: Risk Tolerance Score | D16: 63
B17: Risk Aversion Index (A: 1~20)* | D17: =20*(1-D16/100) -> 7.4
B18: Utility at the risk aversion level | D18: =D13-1/2*D17*D14^2 -> 0.079221256
B19: *Bear (1~5), Normal (1~10), Bull (1~20), Bubble (1~30)
F21: 0.079221256
B22: W of risky pf: y | C22: E(rc) on CAL | D22: 𝜎 c | E22: Utiliity | F22: E(rc) on Indiff.
B23: Max. U | C23: =D13 -> 0.11598251 | D23: =D14 -> 0.099676851 | E23: =D18 -> 0.079221256 | F23: =$F$21+1/2*$D$17*D23^2 -> 0.11598251
B24: 0.1 | C24: 0.05655131 | D24: 0.019104045 | E24: 0.055200941 | F24: =$F$21+1/2*$D$17*D24^2 -> 0.080571625
B25: 0.2 | C25: 0.07064262 | D25: 0.038208091 | E25: 0.065241145 | F25: =$F$21+1/2*$D$17*D25^2 -> 0.084622731
B26: 0.3 | C26: 0.08473393 | D26: 0.057312136 | E26: 0.07258061 | F26: =$F$21+1/2*$D$17*D26^2 -> 0.091374575
B27: 0.4 | C27: 0.09882524 | D27: 0.076416182 | E27: 0.077219339 | F27: =$F$21+1/2*$D$17*D27^2 -> 0.10082716
B28: 0.5 | C28: 0.11291655 | D28: 0.095520227 | E28: 0.079157329 | F28: =$F$21+1/2*$D$17*D28^2 -> 0.11298048
B29: 0.6 | C29: 0.12700786 | D29: 0.11462427 | E29: 0.078394582 | F29: =$F$21+1/2*$D$17*D29^2 -> 0.12783453
B30: 0.7 | C30: 0.14109917 | D30: 0.13372832 | E30: 0.074931097 | F30: =$F$21+1/2*$D$17*D30^2 -> 0.14538933
B31: 0.8 | C31: 0.15519048 | D31: 0.15283236 | E31: 0.068766874 | F31: =$F$21+1/2*$D$17*D31^2 -> 0.16564486
B32: 0.9 | C32: 0.16928179 | D32: 0.17193641 | E32: 0.059901914 | F32: =$F$21+1/2*$D$17*D32^2 -> 0.18860113
B33: 1 | C33: 0.1833731 | D33: 0.19104045 | E33: 0.048336216 | F33: =$F$21+1/2*$D$17*D33^2 -> 0.21425814

Sheet Asset Classes Allocation
B2: Asset Classes Allocation Analysis: Optimal Complete Pf Model
B3: Capital Allocation > Asset Classes Allocation > Security Selection
B5: Securities | C5: Expected Return | D5: Standard Deviation | E5: Corr. Coefficient B,E | F5: Covariance B,E | H5: Efficient Frontier meets CAL with Optimal Risky Pf
B6: Bond Pf (B) | C6: ='Data. Bond Duration & Convexity'!C16 -> 0.0260605 | D6: ='Data. Securities'!O8 -> 0.028165402 | E6: =CORREL('Data. Securities'!AU57:AU176,'Data. Securities'!AX57:AX176) -> 0.47856013 | F6: =$D$6*$D$7*$E$6 -> 0.0025750034
B7: Equity Pf (E) | C7: ='Security Allocation'!C65+C8 -> 0.1833731 | D7: ='Security Allocation'!C66 -> 0.19104045
B8: T-Bill | C8: 0.04246 | D8: 0
B10: Risky Asset Portfolio: Weights | F10: Reward to Variability
B11: Bond weight | C11: Equity weight | D11: Expected Return | E11: Standard Deviation | F11: (Sharpe ratio)
B12: 1 | C12: 0 | D12: =$C$6*$B12+$C$7*$C12 -> 0.0260605 | E12: =($B12^2*$D$6^2+$C12^2*$D$7^2+2*$B12*$C12*$F$6)^0.5 -> 0.028165402 | F12: =(D12-$C$8)/E12 -> -0.58225691
B13: 0.9 | C13: 0.1 | D13: =$C$6*$B13+$C$7*$C13 -> 0.04179176 | E13: =($B13^2*$D$6^2+$C13^2*$D$7^2+2*$B13*$C13*$F$6)^0.5 -> 0.038354009 | F13: =(D13-$C$8)/E13 -> -0.017422951
B14: 0.8 | C14: 0.2 | D14: =$C$6*$B14+$C$7*$C14 -> 0.05752302 | E14: =($B14^2*$D$6^2+$C14^2*$D$7^2+2*$B14*$C14*$F$6)^0.5 -> 0.052835261 | F14: =(D14-$C$8)/E14 -> 0.28509408
B15: 0.7 | C15: 0.3 | D15: =$C$6*$B15+$C$7*$C15 -> 0.07325428 | E15: =($B15^2*$D$6^2+$C15^2*$D$7^2+2*$B15*$C15*$F$6)^0.5 -> 0.068955743 | F15: =(D15-$C$8)/E15 -> 0.44658035
B16: 0.6 | C16: 0.4 | D16: =$C$6*$B16+$C$7*$C16 -> 0.08898554 | E16: =($B16^2*$D$6^2+$C16^2*$D$7^2+2*$B16*$C16*$F$6)^0.5 -> 0.08579638 | F16: =(D16-$C$8)/E16 -> 0.54227859
B17: 0.5 | C17: 0.5 | D17: =$C$6*$B17+$C$7*$C17 -> 0.1047168 | E17: =($B17^2*$D$6^2+$C17^2*$D$7^2+2*$B17*$C17*$F$6)^0.5 -> 0.10300455 | F17: =(D17-$C$8)/E17 -> 0.60440823
B18: 0.4 | C18: 0.6 | D18: =$C$6*$B18+$C$7*$C18 -> 0.12044806 | E18: =($B18^2*$D$6^2+$C18^2*$D$7^2+2*$B18*$C18*$F$6)^0.5 -> 0.1204228 | F18: =(D18-$C$8)/E18 -> 0.6476187
B19: 0.3 | C19: 0.7 | D19: =$C$6*$B19+$C$7*$C19 -> 0.13617932 | E19: =($B19^2*$D$6^2+$C19^2*$D$7^2+2*$B19*$C19*$F$6)^0.5 -> 0.13797159 | F19: =(D19-$C$8)/E19 -> 0.67926533
B20: 0.2 | C20: 0.8 | D20: =$C$6*$B20+$C$7*$C20 -> 0.15191058 | E20: =($B20^2*$D$6^2+$C20^2*$D$7^2+2*$B20*$C20*$F$6)^0.5 -> 0.15560676 | F20: =(D20-$C$8)/E20 -> 0.70337934
B21: 0.1 | C21: 0.9 | D21: =$C$6*$B21+$C$7*$C21 -> 0.16764184 | E21: =($B21^2*$D$6^2+$C21^2*$D$7^2+2*$B21*$C21*$F$6)^0.5 -> 0.17330194 | F21: =(D21-$C$8)/E21 -> 0.72233375
B22: 0 | C22: 1 | D22: =$C$6*$B22+$C$7*$C22 -> 0.1833731 | E22: =($B22^2*$D$6^2+$C22^2*$D$7^2+2*$B22*$C22*$F$6)^0.5 -> 0.19104045 | F22: =(D22-$C$8)/E22 -> 0.73760869
B23: A. Minimum Variance Portfolio of Risky Assets | D23: Expected Return | E23: Min. Standard Deviation | F23: Sharpe Ratio
B24: 1 | C24: =1-$B$24 -> 0 | D24: =$C$6*$B24+$C$7*$C24 -> 0.0260605 | E24: =((($B$24^2)*($D$6^2))+(($C$24^2)*($D$7^2))+(2*$B$24*$C$24*$F$6))^0.5 -> 0.028165402 | F24: =(D24-$C$8)/E24 -> -0.58225691 | G24: short-not allowed
B25: B. Optimal Risky Portfolio. Maximum of Sharpe ratio | D25: Expected Return | E25: Standard Deviation | F25: Max. of Sharpe Ratio
B26: 0 | C26: =1-B26 -> 1 | D26: =$C$6*$B26+$C$7*$C26 -> 0.1833731 | E26: =((($B$26^2)*($D$6^2))+(($C$26^2)*($D$7^2))+(2*$B$26*$C$26*$F$6))^0.5 -> 0.19104045 | F26: =(D26-$C$8)/E26 -> 0.73760869 | G26: short-not allowed
B28: C. Optimal Complete Portfolio with U w/ Risk-Free Asset
B29: Weight y: Optimal Risky Portfolio | D29: =(D26-C8)/('Capital Allocation'!D17*'Asset Classes Allocation'!E26^2) -> 0.52175782
B30: Weight (1-y): Risk-Free Asset | D30: =1-D29 -> 0.47824218
B31: Bond weight in the Optimal Complete Pf | D31: =D29*B26 -> 0
B32: Equity weight in the Optimal Complete Pf | D32: =D29*C26 -> 0.52175782
B33: E(rc): expected return of the Overall Complete pf | D33: =D29*D26+D30*C8 -> 0.11598251
B34: 𝜎 c: SD of Overall Complete pf | D34: =D29*E26 -> 0.099676851
B35: Sharpe Ratio (Max. Slope of CAL) | D35: =(D33-C8)/D34 -> 0.73760869

Sheet Security Allocation
B2: Index Portfolio Model. SPDR + Active Portfolio (Large Growth)
B4: Panel A. Risk Parameters of Pf A (annualized) | C4: ='Data. Securities'!F6 -> IYC | D4: ='Data. Securities'!G6 -> AMZN | E4: ='Data. Securities'!H6 -> TSLA | F4: ='Data. Securities'!I6 -> COST | G4: ='Data. Securities'!J6 -> NFLX | H4: ='Data. Securities'!K6 -> BKNG | I4: ='Data. Securities'!L6 -> HD | J4: ='Data. Securities'!M6 -> SBUX | K4: ='Data. Securities'!N6 -> WMT
B5: Beta | C5: ='Data. Securities'!F17 -> 1 | D5: ='Data. Securities'!G17 -> 1.1614255 | E5: ='Data. Securities'!H17 -> 1.7858873 | F5: ='Data. Securities'!I17 -> 0.73994352 | G5: ='Data. Securities'!J17 -> 1.1486187 | H5: ='Data. Securities'!K17 -> 1.0050217 | I5: ='Data. Securities'!L17 -> 0.85338102 | J5: ='Data. Securities'!M17 -> 0.73534517 | K5: ='Data. Securities'!N17 -> 0.46119564
B6: SD of Excess Return | C6: ='Data. Securities'!F8 -> 0.18920755 | D6: ='Data. Securities'!G8 -> 0.31095122 | E6: ='Data. Securities'!H8 -> 0.63117784 | F6: ='Data. Securities'!I8 -> 0.20993206 | G6: ='Data. Securities'!J8 -> 0.41059796 | H6: ='Data. Securities'!K8 -> 0.29486101 | I6: ='Data. Securities'!L8 -> 0.22083305 | J6: ='Data. Securities'!M8 -> 0.24911038 | K6: ='Data. Securities'!N8 -> 0.19097089
B7: SD of Residual (e), Firm specific Component | C7: ='Data. Securities'!F10 -> 0 | D7: ='Data. Securities'!G10 -> 0.22000089 | E7: ='Data. Securities'!H10 -> 0.53310342 | F7: ='Data. Securities'!I10 -> 0.15643099 | G7: ='Data. Securities'!J10 -> 0.34836694 | H7: ='Data. Securities'!K10 -> 0.22535098 | I7: ='Data. Securities'!L10 -> 0.15065167 | J7: ='Data. Securities'!M10 -> 0.20663502 | K7: ='Data. Securities'!N10 -> 0.16986841
B8: SD of Systematic Component | C8: =C5*$C$6 -> 0.18920755 | D8: =D5*$C$6 -> 0.21975048 | E8: =E5*$C$6 -> 0.33790336 | F8: =F5*$C$6 -> 0.1400029 | G8: =G5*$C$6 -> 0.21732732 | H8: =H5*$C$6 -> 0.19015769 | I8: =I5*$C$6 -> 0.16146613 | J8: =J5*$C$6 -> 0.13913286 | K8: =K5*$C$6 -> 0.087261696
B9: Correlation with the Market Index | C9: =C5*$C$6/C6 -> 1 | D9: =D5*$C$6/D6 -> 0.70670402 | E9: =E5*$C$6/E6 -> 0.53535365 | F9: =F5*$C$6/F6 -> 0.66689625 | G9: =G5*$C$6/G6 -> 0.52929469 | H9: =H5*$C$6/H6 -> 0.6449062 | I9: =I5*$C$6/I6 -> 0.73116831 | J9: =J5*$C$6/J6 -> 0.5585189 | K9: =K5*$C$6/K6 -> 0.45693716
B11: Panel B. Correlation Matrix | C11: =C4 -> IYC | D11: =D4 -> AMZN | E11: =E4 -> TSLA | F11: =F4 -> COST | G11: =G4 -> NFLX | H11: =H4 -> BKNG | I11: =I4 -> HD | J11: =J4 -> SBUX | K11: =K4 -> WMT
B12: {=TRANSPOSE(C11:K11)} -> IYC | C12: ='Data. Securities'!W7 -> 1
B13: AMZN | C13: ='Data. Securities'!W8 -> 0.70670402 | D13: ='Data. Securities'!X8 -> 1
B14: TSLA | C14: ='Data. Securities'!W9 -> 0.53535365 | D14: ='Data. Securities'!X9 -> 0.37833658 | E14: ='Data. Securities'!Y9 -> 1
B15: COST | C15: ='Data. Securities'!W10 -> 0.66689625 | D15: ='Data. Securities'!X10 -> 0.47129826 | E15: ='Data. Securities'!Y10 -> 0.35702534 | F15: ='Data. Securities'!Z10 -> 1
B16: NFLX | C16: ='Data. Securities'!W11 -> 0.52929469 | D16: ='Data. Securities'!X11 -> 0.37405469 | E16: ='Data. Securities'!Y11 -> 0.28335984 | F16: ='Data. Securities'!Z11 -> 0.35298464 | G16: ='Data. Securities'!AA11 -> 1
B17: BKNG | C17: ='Data. Securities'!W12 -> 0.6449062 | D17: ='Data. Securities'!X12 -> 0.45575781 | E17: ='Data. Securities'!Y12 -> 0.34525289 | F17: ='Data. Securities'!Z12 -> 0.43008552 | G17: ='Data. Securities'!AA12 -> 0.34134543 | H17: ='Data. Securities'!AB12 -> 1
B18: HD | C18: ='Data. Securities'!W13 -> 0.73116831 | D18: ='Data. Securities'!X13 -> 0.51671959 | E18: ='Data. Securities'!Y13 -> 0.39143362 | F18: ='Data. Securities'!Z13 -> 0.4876134 | G18: ='Data. Securities'!AA13 -> 0.3870035 | H18: ='Data. Securities'!AB13 -> 0.47153498 | I18: 1
B19: SBUX | C19: ='Data. Securities'!W14 -> 0.5585189 | D19: ='Data. Securities'!X14 -> 0.39470755 | E19: ='Data. Securities'!Y14 -> 0.29900513 | F19: ='Data. Securities'!Z14 -> 0.37247416 | G19: ='Data. Securities'!AA14 -> 0.29562109 | H19: ='Data. Securities'!AB14 -> 0.3601923 | I19: ='Data. Securities'!AC14 -> 0.40837132 | J19: 1
B20: WMT | C20: ='Data. Securities'!W15 -> 0.45693716 | D20: ='Data. Securities'!X15 -> 0.32291933 | E20: ='Data. Securities'!Y15 -> 0.24462297 | F20: ='Data. Securities'!Z15 -> 0.30472967 | G20: ='Data. Securities'!AA15 -> 0.24185441 | H20: ='Data. Securities'!AB15 -> 0.29468161 | I20: ='Data. Securities'!AC15 -> 0.33409797 | J20: ='Data. Securities'!AD15 -> 0.25520804 | K20: ='Data. Securities'!AE15 -> 1
B22: Panel C. The Index Model Covariance Matrix | C22: =C4 -> IYC | D22: =D4 -> AMZN | E22: =E4 -> TSLA | F22: =F4 -> COST | G22: =G4 -> NFLX | H22: =H4 -> BKNG | I22: =I4 -> HD | J22: =J4 -> SBUX | K22: =K4 -> WMT
B23: {=TRANSPOSE(C22:K22)} -> IYC | C23: ='Data. Securities'!W23 -> 0.035799496
B24: AMZN | C24: ='Data. Securities'!W24 -> 0.04157845 | D24: ='Data. Securities'!X24 -> 0.096690663
B25: TSLA | C25: ='Data. Securities'!W25 -> 0.063933866 | D25: ='Data. Securities'!X25 -> 0.074254426 | E25: ='Data. Securities'!Y25 -> 0.39838547
B26: COST | C26: ='Data. Securities'!W26 -> 0.026489605 | D26: ='Data. Securities'!X26 -> 0.030765704 | E26: ='Data. Securities'!Y26 -> 0.04730745 | F26: ='Data. Securities'!Z26 -> 0.044071468
B27: NFLX | C27: ='Data. Securities'!W27 -> 0.041119969 | D27: ='Data. Securities'!X27 -> 0.047757783 | E27: ='Data. Securities'!Y27 -> 0.073435632 | F27: ='Data. Securities'!Z27 -> 0.041119969 | G27: ='Data. Securities'!AA27 -> 0.16859069
B28: BKNG | C28: ='Data. Securities'!W28 -> 0.035979271 | D28: ='Data. Securities'!X28 -> 0.041787244 | E28: ='Data. Securities'!Y28 -> 0.064254923 | F28: ='Data. Securities'!Z28 -> 0.026622628 | G28: ='Data. Securities'!AA28 -> 0.041326462 | H28: ='Data. Securities'!AB28 -> 0.086943013
B29: HD | C29: ='Data. Securities'!W29 -> 0.030550611 | D29: ='Data. Securities'!X29 -> 0.03548226 | E29: ='Data. Securities'!Y29 -> 0.054559948 | F29: ='Data. Securities'!Z29 -> 0.022605726 | G29: ='Data. Securities'!AA29 -> 0.035091001 | H29: ='Data. Securities'!AB29 -> 0.030704027 | I29: ='Data. Securities'!AC29 -> 0.048767237
B30: SBUX | C30: ='Data. Securities'!W30 -> 0.026324987 | D30: ='Data. Securities'!X30 -> 0.030574512 | E30: ='Data. Securities'!Y30 -> 0.04701346 | F30: ='Data. Securities'!Z30 -> 0.019479003 | G30: ='Data. Securities'!AA30 -> 0.030237371 | H30: ='Data. Securities'!AB30 -> 0.026457183 | I30: ='Data. Securities'!AC30 -> 0.022465244 | J30: ='Data. Securities'!AD30 -> 0.062055983
B31: WMT | C31: ='Data. Securities'!W31 -> 0.016510572 | D31: ='Data. Securities'!X31 -> 0.0191758 | E31: ='Data. Securities'!Y31 -> 0.02948602 | F31: ='Data. Securities'!Z31 -> 0.01221689 | G31: ='Data. Securities'!AA31 -> 0.01896435 | H31: ='Data. Securities'!AB31 -> 0.016593483 | I31: ='Data. Securities'!AC31 -> 0.014089808 | J31: ='Data. Securities'!AD31 -> 0.012140969 | K31: ='Data. Securities'!AE31 -> 0.036469881
B33: Panel D. Correlation of Residuals in Pf A | C33: =C22 -> IYC | D33: =D22 -> AMZN | E33: =E22 -> TSLA | F33: =F22 -> COST | G33: =G22 -> NFLX | H33: =H22 -> BKNG | I33: =I22 -> HD | J33: =J22 -> SBUX | K33: =K22 -> WMT
B34: =B23 -> IYC
B35: =B24 -> AMZN | D35: ='Data. Securities'!X41 -> 1
B36: =B25 -> TSLA | D36: ='Data. Securities'!X42 -> 0.26088773 | E36: ='Data. Securities'!Y42 -> 1
B37: =B26 -> COST | D37: ='Data. Securities'!X43 -> 0.019469349 | E37: ='Data. Securities'!Y43 -> -0.12841119 | F37: ='Data. Securities'!Z43 -> 1
B38: =B27 -> NFLX | D38: ='Data. Securities'!X44 -> 0.30830061 | E38: ='Data. Securities'!Y44 -> -0.10310986 | F38: ='Data. Securities'!Z44 -> 0.017329326 | G38: ='Data. Securities'!AA44 -> 1
B39: =B28 -> BKNG | D39: ='Data. Securities'!X45 -> -0.40652006 | E39: ='Data. Securities'!Y45 -> -0.17503211 | F39: ='Data. Securities'!Z45 -> -0.16104884 | G39: ='Data. Securities'!AA45 -> -0.14038944 | H39: ='Data. Securities'!AB45 -> 1
B40: =B29 -> HD | D40: ='Data. Securities'!X46 -> -0.17725928 | E40: ='Data. Securities'!Y46 -> -0.11436499 | F40: ='Data. Securities'!Z46 -> 0.10925128 | G40: ='Data. Securities'!AA46 -> -0.17299556 | H40: ='Data. Securities'!AB46 -> -0.14972495 | I40: ='Data. Securities'!AC46 -> 1
B41: =B30 -> SBUX | D41: ='Data. Securities'!X47 -> -0.17951429 | E41: ='Data. Securities'!Y47 -> -0.24836382 | F41: ='Data. Securities'!Z47 -> 0.10414663 | G41: ='Data. Securities'!AA47 -> -0.11196059 | H41: ='Data. Securities'!AB47 -> 0.081086814 | I41: ='Data. Securities'!AC47 -> 0.030903431 | J41: ='Data. Securities'!AD47 -> 1
B42: =B31 -> WMT | D42: ='Data. Securities'!X48 -> -0.17013126 | E42: ='Data. Securities'!Y48 -> -0.04729219 | F42: ='Data. Securities'!Z48 -> 0.35381387 | G42: ='Data. Securities'!AA48 -> -0.13214638 | H42: ='Data. Securities'!AB48 -> -0.14690693 | I42: ='Data. Securities'!AC48 -> 0.025872186 | J42: ='Data. Securities'!AD48 -> -0.014073774 | K42: ='Data. Securities'!AE48 -> 1
B44: Panel E. Macro Forecast and Alpha Forecasts | C44: =C4 -> IYC | D44: =D4 -> AMZN | E44: =E4 -> TSLA | F44: =F4 -> COST | G44: =G4 -> NFLX | H44: =H4 -> BKNG | I44: =I4 -> HD | J44: =J4 -> SBUX | K44: =K4 -> WMT
B45: Adjusted Alpha | C45: ='Data. Securities'!F16 -> 0 | D45: ='Data. Securities'!G16 -> 0.12258895 | E45: ='Data. Securities'!H16 -> 0.067040669 | F45: ='Data. Securities'!I16 -> 0.058475126 | G45: ='Data. Securities'!J16 -> 0.1378241 | H45: ='Data. Securities'!K16 -> 0.068760739 | I45: ='Data. Securities'!L16 -> 0.04323193 | J45: ='Data. Securities'!M16 -> 0.0084348087 | K45: ='Data. Securities'!N16 -> 0.044231075
B46: Beta | C46: ='Data. Securities'!F17 -> 1 | D46: ='Data. Securities'!G17 -> 1.1614255 | E46: ='Data. Securities'!H17 -> 1.7858873 | F46: ='Data. Securities'!I17 -> 0.73994352 | G46: ='Data. Securities'!J17 -> 1.1486187 | H46: ='Data. Securities'!K17 -> 1.0050217 | I46: ='Data. Securities'!L17 -> 0.85338102 | J46: ='Data. Securities'!M17 -> 0.73534517 | K46: ='Data. Securities'!N17 -> 0.46119564
...

Sheet Data. Securities
B2: Data. Security Index Model
B4: Panel 1. Risk & Return Parameters in the Security Index Model | U4: Panel 2. Correlation and Covariance Matrixs in the Security Index Model
B6: Estimates annualized | E6: T-bill | F6: IYC | G6: AMZN | H6: TSLA | I6: COST | J6: NFLX | K6: BKNG | L6: HD | M6: SBUX | N6: WMT | O6: IGSB | V6: Correl (via Index) | W6: =F6 -> IYC | X6: =G6 -> AMZN | Y6: =H6 -> TSLA | Z6: =I6 -> COST | AA6: =J6 -> NFLX | AB6: =K6 -> BKNG | AC6: =L6 -> HD | AD6: =M6 -> SBUX | AE6: =N6 -> WMT
B7: Expected excess return | E7: 0.04246 | F7: =AVERAGE(E57:E176)*12 -> 0.065117414 | G7: =AVERAGE(H57:H176)*12 -> 0.2390791 | H7: =AVERAGE(M57:M176)*12 -> 0.44280844 | I7: =AVERAGE(R57:R176)*12 -> 0.17290167 | J7: =AVERAGE(W57:W176)*12 -> 0.32314709 | K7: =AVERAGE(AB57:AB176)*12 -> 0.13895424 | L7: =AVERAGE(AG57:AG176)*12 -> 0.099386223 | M7: =AVERAGE(AL57:AL176)*12 -> 0.061304652 | N7: =AVERAGE(AQ57:AQ176)*12 -> 0.09267216 | O7: =AVERAGE(AX57:AX176)*12 -> -0.042807137 | V7: IYC | W7: 1
B8: SD of Excess Return | F8: =_xlfn.STDEV.S(E57:E176)*SQRT(12) -> 0.18920755 | G8: =_xlfn.STDEV.S(H57:H176)*SQRT(12) -> 0.31095122 | H8: =_xlfn.STDEV.S(M57:M176)*SQRT(12) -> 0.63117784 | I8: =_xlfn.STDEV.S(R57:R176)*SQRT(12) -> 0.20993206 | J8: =_xlfn.STDEV.S(W57:W176)*SQRT(12) -> 0.41059796 | K8: =_xlfn.STDEV.S(AB57:AB176)*SQRT(12) -> 0.29486101 | L8: =_xlfn.STDEV.S(AG57:AG176)*SQRT(12) -> 0.22083305 | M8: =_xlfn.STDEV.S(AL57:AL176)*SQRT(12) -> 0.24911038 | N8: =_xlfn.STDEV.S(AQ57:AQ176)*SQRT(12) -> 0.19097089 | O8: =_xlfn.STDEV.S(AX57:AX176)*SQRT(12) -> 0.028165402 | V8: =X6 -> AMZN | W8: =G18 -> 0.70670402 | X8: 1
B9: Sharpe Ratio | F9: =F7/F8 -> 0.34415865 | G9: =G7/G8 -> 0.76886368 | H9: =H7/H8 -> 0.70155891 | I9: =I7/I8 -> 0.82360776 | J9: =J7/J8 -> 0.78701582 | K9: =K7/K8 -> 0.47125334 | L9: =L7/L8 -> 0.45005139 | M9: =M7/M8 -> 0.24609433 | ... O9: =O7/O8 -> -1.5198483 | V9: =Y6 -> TSLA | W9: =H18 -> 0.53535365 | X9: =G18*H18 -> 0.37833658 | Y9: 1
B10: SD of Residuals (e) | F10: 0 | G10: =_xlfn.STDEV.S(J57:J176)*SQRT(12) -> 0.22000089 | H10: =_xlfn.STDEV.S(O57:O176)*SQRT(12) -> 0.53310342 | I10: =_xlfn.STDEV.S(T57:T176)*SQRT(12) -> 0.15643099 | J10: =_xlfn.STDEV.S(Y57:Y176)*SQRT(12) -> 0.34836694 | K10: =_xlfn.STDEV.S(AD57:AD176)*SQRT(12) -> 0.22535098 | L10: =_xlfn.STDEV.S(AI57:AI176)*SQRT(12) -> 0.15065167 | M10: =_xlfn.STDEV.S(AN57:AN176)*SQRT(12) -> 0.20663502 | N10: =_xlfn.STDEV.S(AS57:AS176)*SQRT(12) -> 0.16986841 | V10: =Z6 -> COST | W10: =I18 -> 0.66689625 | X10: =G18*I18 -> 0.47129826 | Y10: =H18*I18 -> 0.35702534 | Z10: 1
B11: SD of Systematic component | F11: =F8 -> 0.18920755 | G11: =_xlfn.STDEV.S(I57:I176)*SQRT(12) -> 0.21975048 | H11: =_xlfn.STDEV.S(N57:N176)*SQRT(12) -> 0.33790336 | I11: =_xlfn.STDEV.S(S57:S176)*SQRT(12) -> 0.1400029 | J11: =_xlfn.STDEV.S(X57:X176)*SQRT(12) -> 0.21732732 | K11: =_xlfn.STDEV.S(AC57:AC176)*SQRT(12) -> 0.19015769 | L11: =_xlfn.STDEV.S(AH57:AH176)*SQRT(12) -> 0.16146613 | M11: =_xlfn.STDEV.S(AM57:AM176)*SQRT(12) -> 0.13913286 | N11: =_xlfn.STDEV.S(AR57:AR176)*SQRT(12) -> 0.087261696 | V11: =AA6 -> NFLX | W11: =J18 -> 0.52929469 | X11: =G18*J18 -> 0.37405469 | Y11: =H18*J18 -> 0.28335984 | Z11: =I18*J18 -> 0.35298464 | AA11: 1
B12: Covariance | F12: =F8^2 -> 0.035799496 | G12: =_xlfn.COVARIANCE.P($E$57:$E$176,H57:H176)*12 -> 0.041231963 | H12: =_xlfn.COVARIANCE.P($E$57:$E$176,M57:M176)*12 -> 0.063401084 | I12: =_xlfn.COVARIANCE.P($E$57:$E$176,R57:R176)*12 -> 0.026268859 | J12: =_xlfn.COVARIANCE.P($E$57:$E$176,W57:W176)*12 -> 0.040777303 | K12: =_xlfn.COVARIANCE.P($E$57:$E$176,AB57:AB176)*12 -> 0.035679444 | L12: =_xlfn.COVARIANCE.P($E$57:$E$176,AG57:AG176)*12 -> 0.030296022 | M12: =_xlfn.COVARIANCE.P($E$57:$E$176,AL57:AL176)*12 -> 0.026105612 | N12: =_xlfn.COVARIANCE.P($E$57:$E$176,AQ57:AQ176)*12 -> 0.016372983 | V12: =AB6 -> BKNG | W12: =K18 -> 0.6449062 | X12: =G18*K18 -> 0.45575781 | Y12: =H18*K18 -> 0.34525289 | Z12: =I18*K18 -> 0.43008552 | AA12: =J18*K18 -> 0.34134543 | AB12: 1
B13: Alpha (Non-market risk premium in the index model) | F13: 0 | G13: =INTERCEPT(H57:H176,$E$57:$E$176)*12 -> 0.16345007 | H13: =INTERCEPT(M57:M176,$E$57:$E$176)*12 -> 0.32651608 | I13: =INTERCEPT(R57:R176,$E$57:$E$176)*12 -> 0.12471846 | J13: =INTERCEPT(W57:W176,$E$57:$E$176)*12 -> 0.24835202 | K13: =INTERCEPT(AB57:AB176,$E$57:$E$176)*12 -> 0.073509822 | L13: =INTERCEPT(AG57:AG176,$E$57:$E$176)*12 -> 0.043816258 | M13: =INTERCEPT(AL57:AL176,$E$57:$E$176)*12 -> 0.013420877 | N13: =INTERCEPT(AQ57:AQ176,$E$57:$E$176)*12 -> 0.062640293 | V13: HD | W13: =L18 -> 0.73116831 | X13: =G18*L18 -> 0.51671959 | Y13: =H18*L18 -> 0.39143362 | Z13: =I18*L18 -> 0.4876134 | AA13: =J18*L18 -> 0.3870035 | AB13: =K18*L18 -> 0.47153498 | AC13: 1
B14: Adjusted Alpha (a x avg. Market PE / Stock PE) | F14: 0 | G14: =G13*$E$27/G27 -> 0.12675234 | H14: =H13*$E$27/H27 -> 0.068779649 | I14: =I13*$E$27/I27 -> 0.060124052 | J14: =J13*$E$27/J27 -> 0.14083506 | K14: =K13*$E$27/K27 -> 0.073399571 | L14: =L13*$E$27/L27 -> 0.047509241 | M14: =M13*$E$27/M27 -> 0.011295763 | N14: =N13*$E$27/N27 -> 0.045789486 | V14: SBUX | W14: =M18 -> 0.5585189 | X14: =G18*M18 -> 0.39470755 | Y14: =H18*M18 -> 0.29900513 | Z14: =I18*M18 -> 0.37247416 | AA14: =J18*M18 -> 0.29562109 | AB14: =K18*M18 -> 0.3601923 | AC14: =L18*M18 -> 0.40837132 | AD14: 1
B15: Alpha in CAPM (10 yrs market premium) | F15: 0 | G15: =(G7+$E$7-(4.246%+G17*(11.22%-4.246%))) -> 0.15808128 | H15: =(H7+$E$7-(4.246%+H17*(11.22%-4.246%))) -> 0.31826066 | I15: =(I7+$E$7-(4.246%+I17*(11.22%-4.246%))) -> 0.12129801 | J15: =(J7+$E$7-(4.246%+J17*(11.22%-4.246%))) -> 0.24304243 | K15: =(K7+$E$7-(4.246%+K17*(11.22%-4.246%))) -> 0.068864022 | L15: =(L7+$E$7-(4.246%+L17*(11.22%-4.246%))) -> 0.039871431 | M15: =(M7+$E$7-(4.246%+M17*(11.22%-4.246%))) -> 0.01002168 | N15: =(N7+$E$7-(4.246%+N17*(11.22%-4.246%))) -> 0.060508376 | V15: WMT | W15: =N18 -> 0.45693716 | X15: =G18*N18 -> 0.32291933 | Y15: =H18*N18 -> 0.24462297 | Z15: =I18*N18 -> 0.30472967 | AA15: =J18*N18 -> 0.24185441 | AB15: =K18*N18 -> 0.29468161 | AC15: =L18*N18 -> 0.33409797 | AD15: =M18*N18 -> 0.25520804 | AE15: 1
B16: Adjusted Alpha in CAPM (a x avg. Market PE / Stock PE) | F16: 0 | G16: =G15*$E$27/G27 -> 0.12258895 | H16: =H15*$E$27/H27 -> 0.067040669 | I16: =I15*$E$27/I27 -> 0.058475126 | J16: =J15*$E$27/J27 -> 0.1378241 | K16: =K15*$E$27/K27 -> 0.068760739 | L16: =L15*$E$27/L27 -> 0.04323193 | M16: =M15*$E$27/M27 -> 0.0084348087 | N16: =N15*$E$27/N27 -> 0.044231075
B17: Beta | F17: 1 | G17: =SLOPE(H57:H176,$E$57:$E$176) -> 1.1614255 | H17: =SLOPE(M57:M176,$E$57:$E$176) -> 1.7858873 | I17: =SLOPE(R57:R176,$E$57:$E$176) -> 0.73994352 | J17: =SLOPE(W57:W176,$E$57:$E$176) -> 1.1486187 | K17: =SLOPE(AB57:AB176,$E$57:$E$176) -> 1.0050217 | L17: =SLOPE(AG57:AG176,$E$57:$E$176) -> 0.85338102 | M17: =SLOPE(AL57:AL176,$E$57:$E$176) -> 0.73534517 | N17: =SLOPE(AQ57:AQ176,$E$57:$E$176) -> 0.46119564
B18: Correlation with Index | F18: 1 | G18: =CORREL(H57:H176,$E$57:$E$176) -> 0.70670402 | H18: =CORREL(M57:M176,$E$57:$E$176) -> 0.53535365 | I18: =CORREL(R57:R176,$E$57:$E$176) -> 0.66689625 | J18: =CORREL(W57:W176,$E$57:$E$176) -> 0.52929469 | K18: =CORREL(AB57:AB176,$E$57:$E$176) -> 0.6449062 | L18: =CORREL(AG57:AG176,$E$57:$E$176) -> 0.73116831 | M18: =CORREL(AL57:AL176,$E$57:$E$176) -> 0.5585189 | N18: =CORREL(AQ57:AQ176,$E$57:$E$176) -> 0.45693716 | P18: =CORREL(E57:E176,AX57:AX176) -> 0.53898049
B19: R Squared (Market Determination) | F19: 1 | G19: =G18^2 -> 0.49943058 | H19: =H18^2 -> 0.28660353 | I19: =I18^2 -> 0.4447506 | J19: =J18^2 -> 0.28015287 | K19: =K18^2 -> 0.41590401 | L19: =L18^2 -> 0.5346071 | M19: =M18^2 -> 0.31194336 | N19: =N18^2 -> 0.20879157
B20: 1-R Squared (Firms Specific) | F20: 1 | G20: =1-G19 -> 0.50056942 | H20: =1-H19 -> 0.71339647 | I20: =1-I19 -> 0.5552494 | J20: =1-J19 -> 0.71984713 | K20: =1-K19 -> 0.58409599 | L20: =1-L19 -> 0.4653929 | M20: =1-M19 -> 0.68805664 | N20: =1-N19 -> 0.79120843
B21: Pf Style. | C21: Value / Blend / Growth | F21: Large Growth | G21: Growth | H21: Growth | I21: Blend | J21: Growth | K21: Growth | L21: Blend | M21: Growth | N21: Blend | P21: Credit (Investment / High Yield)
C22: Small / Medium / Large | G22: Large | H22: Large | I22: Large | J22: Large | K22: Large | L22: Large | M22: Large | N22: Large | P22: Duration (longer / shorter) | V22: Covariance (via Index) | W22: =W6 -> IYC | X22: =X6 -> AMZN | Y22: =Y6 -> TSLA | Z22: =Z6 -> COST | AA22: =AA6 -> NFLX | AB22: =AB6 -> BKNG | AC22: =AC6 -> HD | AD22: =AD6 -> SBUX | AE22: =AE6 -> WMT
C23: Sector (industry) | G23: Consumer Discretionary | H23: Consumer Discretionary | I23: Consumer Staples | J23: Communication | K23: Consumer Discretionary | L23: Consumer Discretionary | M23: Consumer Discretionary | N23: Consumer Staples | P23: Issuers (Corporate / Government) | V23: IYC | W23: =F8^2 -> 0.035799496
C24: Themes | G24: E commerce | H24: Renewable Energy | I24: Retail | J24: Streaming | K24: Travel | L24: Retail | M24: Retail | N24: Retail | P24: Inflation / close-ended / sector… | V24: =X22 -> AMZN | W24: =G17*1*W23 -> 0.04157845 | X24: =G8^2 -> 0.096690663
B25: Stock Info. | C25: Current Stock Price (as of March 31st) | G25: 190.26 | H25: 259.16 | I25: 945.78 | J25: 932.52 | K25: 4606.91 | L25: 366.49 | M25: 98.09 | N25: 87.79 | V25: =Y22 -> TSLA | W25: =$H$17*$W$23 -> 0.063933866 | X25: =$H$17*G17*$W$23 -> 0.074254426 | Y25: =H8^2 -> 0.39838547
C26: EPS (TTM) | G26: 5.54 | H26: 2.05 | I26: 17.12 | J26: 19.86 | K26: 172.76 | L26: 14.92 | M26: 3.1 | N26: 2.41 | V26: =Z22 -> COST | W26: =$I$17*1*$W$23 -> 0.026489605 | X26: =$I$17*G17*$W$23 -> 0.030765704 | Y26: =$I$17*H17*$W$23 -> 0.04730745 | Z26: =I8^2 -> 0.044071468
C27: PE Ratio (TTM) | E27: 26.63 | F27: 24.66 | G27: 34.34 | H27: 126.42 | I27: 55.24 | J27: 46.96 | K27: 26.67 | L27: 24.56 | M27: 31.64 | N27: 36.43 | V27: =AA22 -> NFLX | W27: =$J$17*$W$23 -> 0.041119969 | X27: =$J$17*$W$23*G17 -> 0.047757783 | Y27: =$J$17*$W$23*H17 -> 0.073435632 | Z27: =$J$17*$W$23 -> 0.041119969 | AA27: =J8^2 -> 0.16859069
C28: 1y Forward Dividend ($) | I28: 4.64 | K28: 38.4 | L28: 9.2 | M28: 2.44 | N28: 0.94 | V28: =AB22 -> BKNG | W28: =$K$17*$W$23 -> 0.035979271 | X28: =$K$17*$W$23*G17 -> 0.041787244 | Y28: =$K$17*$W$23*H17 -> 0.064254923 | Z28: =$K$17*$W$23*I17 -> 0.026622628 | AA28: =$K$17*$W$23*J17 -> 0.041326462 | AB28: =K8^2 -> 0.086943013
C29: 1y Forward Dividend Yield (%) | I29: 0.0049 | K29: 0.0083 | L29: 0.0251 | M29: 0.0249 | N29: 0.0107 | V29: HD | W29: =$L$17*$W$23 -> 0.030550611 | X29: =$L$17*$W$23*G17 -> 0.03548226 | Y29: =$L$17*$W$23*H17 -> 0.054559948 | Z29: =$L$17*$W$23*I17 -> 0.022605726 | AA29: =$L$17*$W$23*J17 -> 0.035091001 | AB29: =$L$17*$W$23*K17 -> 0.030704027 | AC29: =L8^2 -> 0.048767237
C30: 1y Target Est. (Consensus) | G30: 264.59 | H30: 329.91 | I30: 1063.16 | J30: 1073.96 | K30: 5636.98 | L30: 431.5 | M30: 107.51 | N30: 108.11 | V30: SBUX | W30: =$M$17*$W$23 -> 0.026324987 | X30: =$M$17*$W$23*G17 -> 0.030574512 | Y30: =$M$17*$W$23*H17 -> 0.04701346 | Z30: =$M$17*$W$23*I17 -> 0.019479003 | AA30: =$M$17*$W$23*J17 -> 0.030237371 | AB30: =$M$17*$W$23*K17 -> 0.026457183 | AC30: =$M$17*$W$23*L17 -> 0.022465244 | AD30: =M8^2 -> 0.062055983
C31: 1y Target return ` | G31: =(G30-G25)/G25 -> 0.39067592 | H31: =(H30-H25)/H25 -> 0.27299738 | I31: =(I30-I25)/I25 -> 0.1241092 | J31: =(J30-J25)/J25 -> 0.15167503 | K31: =(K30-K25)/K25 -> 0.22359239 | L31: =(L30-L25)/L25 -> 0.17738547 | M31: =(M30-M25)/M25 -> 0.096034254 | N31: =(N30-N25)/N25 -> 0.23146144 | V31: WMT | W31: =$N$17*$W$23 -> 0.016510572 | X31: =$N$17*$W$23*G17 -> 0.0191758 | Y31: =$N$17*$W$23*H17 -> 0.02948602 | Z31: =$N$17*$W$23*I17 -> 0.01221689 | AA31: =$N$17*$W$23*J17 -> 0.01896435 | AB31: =$N$17*$W$23*K17 -> 0.016593483 | AC31: =$N$17*$W$23*L17 -> 0.014089808 | AD31: =$N$17*$W$23*M17 -> 0.012140969 | AE31: =N8^2 -> 0.036469881
B32: Active Pf Weights* (Index model) | F32: ='Security Allocation'!D63 -> 0 | G32: ='Security Allocation'!F63 -> 0.22447578 | H32: ='Security Allocation'!G63 -> 0.020906552 | I32: ='Security Allocation'!H63 -> 0.21178372 | J32: ='Security Allocation'!I63 -> 0.10065105 | K32: ='Security Allocation'!J63 -> 0.12000204 | L32: ='Security Allocation'!K63 -> 0.16881994 | M32: ='Security Allocation'!L63 -> 0.017507914 | N32: ='Security Allocation'!M63 -> 0.13585301 | ... R32: ='Security Allocation'!Q63 -> 0
V39: Correl of Residuals | W39: =W6 -> IYC | X39: =X6 -> AMZN | Y39: =Y6 -> TSLA | Z39: =Z6 -> COST | AA39: =AA6 -> NFLX | AB39: =AB6 -> BKNG | AC39: =AC6 -> HD | AD39: =AD6 -> SBUX | AE39: =AE6 -> WMT
V40: IYC
V41: =X39 -> AMZN | X41: 1
V42: =Y39 -> TSLA | X42: =CORREL(J57:J115,O57:O115) -> 0.26088773 | Y42: 1
V43: =Z39 -> COST | X43: =CORREL(J57:J115,T57:T115) -> 0.019469349 | Y43: =CORREL(O57:O115,T57:T115) -> -0.12841119 | Z43: 1
V44: =AA39 -> NFLX | X44: =CORREL(J57:J115,Y57:Y115) -> 0.30830061 | Y44: =CORREL(O57:O115,Y57:Y115) -> -0.10310986 | Z44: =CORREL(T57:T115,Y57:Y115) -> 0.017329326 | AA44: 1
V45: =AB39 -> BKNG | X45: =CORREL(J57:J115,AD57:AD115) -> -0.40652006 | Y45: =CORREL(O57:O115,AD57:AD115) -> -0.17503211 | Z45: =CORREL(T57:T115,AD57:AD115) -> -0.16104884 | AA45: =CORREL(Y57:Y115,AD57:AD115) -> -0.14038944 | AB45: 1
V46: HD | X46: =CORREL(J57:J176,AI57:AI176) -> -0.17725928 | Y46: =CORREL(O57:O176,AI57:AI176) -> -0.11436499 | Z46: =CORREL(T57:T176,AI57:AI176) -> 0.10925128 | AA46: =CORREL(Y57:Y176,AI57:AI176) -> -0.17299556 | AB46: =CORREL(AI57:AI176,AD57:AD176) -> -0.14972495 | AC46: 1
V47: SBUX | X47: =CORREL($AN$57:$AN$176,J57:J176) -> -0.17951429 | Y47: =CORREL($AN$57:$AN$176,O57:O176) -> -0.24836382 | Z47: =CORREL($AN$57:$AN$176,T57:T176) -> 0.10414663 | AA47: =CORREL($AN$57:$AN$176,Y57:Y176) -> -0.11196059 | AB47: =CORREL($AN$57:$AN$176,AD57:AD176) -> 0.081086814 | AC47: =CORREL($AN$57:$AN$176,AI57:AI176) -> 0.030903431 | AD47: 1
V48: WMT | X48: =CORREL($AS$57:$AS$176,J57:J176) -> -0.17013126 | Y48: =CORREL($AS$57:$AS$176,O57:O176) -> -0.04729219 | Z48: =CORREL($AS$57:$AS$176,T57:T176) -> 0.35381387 | AA48: =CORREL($AS$57:$AS$176,Y57:Y176) -> -0.13214638 | AB48: =CORREL($AS$57:$AS$176,AD57:AD176) -> -0.14690693 | AC48: =CORREL($AS$57:$AS$176,AI57:AI176) -> 0.025872186 | AD48: =CORREL($AS$57:$AS$176,AN57:AN176) -> -0.014073774 | AE48: 1
B54: 120 months | C54: iShares U.S. Consumer Discretionary ETF (IYC) | F54: Amazon (AMZN) | K54: Tesla (TSLA) | P54: Costco (COST) | U54: Netflix (NFLX) | Z54: Booking Holdings (BKNG) | AE54: Home Depot (HD) | AJ54: Starbucks (SBUX) | AO54: Walmart (WMT) | AT54: Equity Pf | AV54: Bond Pf (IGSB) | AZ54: Benchmark Check
...

Sheet Data. Bond Duration & Convexity
B2: Calculate the approximate price change for a IGSB using only its D* and using D* and Convexity
B4: IGSB has the following characteristics:
B5: Maturity | C5: 13
B6: Coupon ($100 par) | C6: 0.0424
B7: Yield to maturity | C7: 0.0526
B8: Coupon (frequency) | C8: Semiannual
B9: Convexity (C) | C9: 1.21
B10: Current Bond Price | C10: =PV(C7/2,C5*2,-C6/2*100,-100) -> 90.482109 | D10: =_xlfn.FORMULATEXT(C10) -> =PV(C7/2,C5*2,-C6/2*100,-100)
B11: Modified Duration (D*) | C11: 2.6
B13: Changes in YTM | C13: YTM down 100bps
B14: with D* only | C14: =-C11*-1% -> 0.026 | D14: =_xlfn.FORMULATEXT(C14) -> =-C11*-1%
B15: Bond Price change | C15: =C10*(1+C14) -> 92.834644 | D15: =_xlfn.FORMULATEXT(C15) -> =C10*(1+C14)
B16: with D* and Convexity | C16: =C14+1/2*C9*-1%^2 -> 0.0260605 | D16: =_xlfn.FORMULATEXT(C16) -> =C14+1/2*C9*-1%^2
B17: Bond Price change | C17: =C10*(1+C16) -> 92.840118 | D17: =_xlfn.FORMULATEXT(C17) -> =C10*(1+C16)
